Workbook
Name koralbeton: #REF!
Name bbm: #REF!
Name zzz: #REF!
Name ubinmosaik3030: #REF!
Name _818FA: #REF!
Name rincian: #REF!
Name R56..: #REF!
Name ___DIV2: #REF!
Name venetionblinds: #REF!
Name sementahanasam: #REF!
Name _______MMM42: #REF!
Name bakkontrol: #REF!
Name L: #REF!
Name sdg: #REF!
Name rollingdoor: #REF!
Name ________DIV4: #REF!
Name ________HAL6: #REF!
Name kiki: #REF!
Name kayuterentang: #REF!
Name ______DIV8: #REF!
Name besi10.sii: #REF!
Name kaca.p.5: #REF!
Name URAIAN94: #REF!
Name plamur.matex: #REF!
Name kayujati: #REF!
Name ubinkeramikartistik1010: #REF!
Name _____DIV10: #REF!
Name Kunci1: #REF!
Name ________DIV10: #REF!
Name multi.18: #REF!
Name gymfloor: #REF!
Name jendelanako: #REF!
Name SPJ: #REF!
Name w: #REF!
Name _MMM36: #REF!
Name FORM841: #REF!
Name pakuhalus: #REF!
Name washtafel: #REF!
Name cycllop: #REF!
Name __MMM29: #REF!
Name bubungangentengkodok: #REF!
Name _MMM32: #REF!
Name _tl2: #REF!
Name rollingdoor: #REF!
Name ubinkeramik1033: #REF!
Name UPAH: #REF!
Name URAIAN7614b: #REF!
Name ______HAL5: #REF!
Name __LLL01: #REF!
Name waterstop150: #REF!
Name ubingranito40: #REF!
Name pasirsilika: #REF!
Name ________MMM03: #REF!
Name _________HAL4: #REF!
Name papanjelutung: #REF!
Name kayutembesu: #REF!
Name sodaapi: #REF!
Name tanggal: #REF!
Name urugantanah: #REF!
Name P: #REF!

Sheet 01. Dinas Pendidikan
A2: KARTU INVENTARIS BARANG ( KIB )
A3: B. PERALATAN MESIN ( KENDARAAN RODA 4 ( EMPAT ) DAN 2 ( DUA )
A6: PEMERINTAH PROVINSI | C6: : JAMBI
A7: KABUPATEN / KOTA | C7: : MUARO JAMBI
A8: UNIT ORGANISASI | C8: : DINAS PENDIDIKAN
A9: no | B9: spesifikasi | C9: spesifikasi_lainnya | D9: unit_kerja | E9: kondisi | F9: harga | G9: merk | H9: tahun | I9: no_polisi | J9: no_rangka | K9: no_Mesin | L9: no bpkb | M9: keterangan | N9: pengguna
B10: KENDARAAN BERMOTOR PENUMPANG | F10: =SUBTOTAL(9,F11:F18) -> 1516300000
A11: 1 | B11: Mini Bus | C11: Ada | D11: Dinas Pendidikan dan Kebudayaan | E11: Rusak Berat | F11: 70000000 | G11: Isuzu TBR541 LV25 | H11: 2000 | I11: BH 1140 G EX BH 441 GZ | J11: MHCTBR54BYK083723 | K11: E083723 | L11: A-9091859 | M11: Plat Baru BH 1140 G | N11: Bambang Wigiyanto, A.Md Bendahara Pengeluaran
A12: 2 | B12: Mini Bus | C12: Ada | D12: Dinas Pendidikan dan Kebudayaan | E12: Rusak Berat | F12: 126200000 | G12: Daihatsu Terrios TS | H12: 2007 | I12: BH 1060 GZ | J12: MHKG2CJIJK001781 | K12: DAE1521 | L12: E-6734067
A13: 3 | B13: Mini Bus | C13: Ada | D13: Dinas Pendidikan dan Kebudayaan | E13: Kurang Baik | F13: 206250000 | G13: Mitsubitshi L.300+AC | H13: 2012 | I13: BH 1158 GZ | J13: MHML0WY39CK007241 | K13: 4D56C-H54440 | L13: J-03565887 | N13: Pengurus Barang Pengguna
A14: 4 | B14: Minibus Double Cabin | C14: Ada | D14: Dinas Pendidikan dan Kebudayaan | E14: Kurang Baik | F14: 160000000 | G14: Suzuki APV | H14: 2012 | I14: BH 1160 GZ | J14: MHYGDN42VCJ-368299 | K14: G15AID-257750 | L14: J-03571868 | N14: Agustiarso Kasubag Umum dan Kepegawaian
A15: 5 | B15: Mini Bus | C15: Ada | D15: Dinas Pendidikan dan Kebudayaan | E15: Kurang Baik | F15: 214950000 | G15: Rush tipe 1,56 M/T | H15: 2014 | I15: BH 1232 G EX BH 1203 GZ | J15: MHFE2CJ2JEK043744 | K15: 3SZ-DEG1618 | L15: K-06089680 | M15: BH 1232 G | N15: Kabid PAUD dan PNF
A16: 6 | B16: Mini Bus | C16: Ada | D16: Dinas Pendidikan dan Kebudayaan | E16: Rusak Berat | F16: 214950000 | G16: Rush tipe 1,56 M/T | H16: 2014 | I16: BH 1231 G EX BH 1202 GZ | J16: MHFE2CJ2JEK043454 | K16: 3SZ-DEF5612 | L16: K-06089679 | M16: BH 1231 G
A17: 7 | B17: Mini Bus | C17: Ada | D17: Dinas Pendidikan dan Kebudayaan | E17: Baik | F17: 233950000 | G17: Rush tipe 1,56 M/T | H17: 2017 | I17: BH 1006 G | J17: MHFE2CJ2JHK056691 | K17: 3SZDGE3070 | L17: L-10936516 | N17: Kabid SMP
A18: 8 | B18: Mini Bus | D18: Dinas Pendidikan dan Kebudayaan | E18: Kurang Baik | F18: 290000000 | G18: Wulling Cortez 1.5L LUX+CVT | H18: 2019 | I18: BH 1069 G | N18: Sekretaris
B19: ALAT ANGKUTAN BARANG | F19: =SUBTOTAL(9,F20:F21) -> 652911000
A20: 9 | B20: Pick Up Double Cabin | C20: Ada | D20: Dinas Pendidikan dan Kebudayaan | E20: Kurang Baik | F20: 299800000 | G20: Mitsubishi Strada | H20: 2009 | I20: BH 8113 G EX BH 9326 GZ | J20: MMBJN2409D033303 | K20: 4D56UCBL7100 | L20: F-8112119 | M20: BH 8113 G | N20: Kasi Kelembagaan dan Sarana Prasarana SD
A21: 10 | B21: Pick Up Double Cabin | C21: Ada | D21: Dinas Pendidikan dan Kebudayaan | E21: Kurang Baik | F21: 353111000 | G21: Ford | H21: 2013 | I21: BH 8093 G EX BH 9352 GZ | J21: MNBLMFF80CW140661 | K21: P4AT1046052 | L21: K-00103962 | M21: BH 8093 G | N21: Kabid SD
B22: KENDARAAN BERMOTOR BERODA DUA | F22: =SUBTOTAL(9,F23:F176) -> 2464728000
A23: 1 | B23: Sepeda Motor | D23: Dinas Pendidikan dan Kebudayaan | E23: Baik | F23: 1500000 | G23: Suzuki Bravo | H23: 1993 | I23: BH 5428 AZ | J23: MHDA100VxDJ274054 | K23: A100.ID.161536
A24: 2 | B24: Sepeda Motor | D24: Dinas Pendidikan dan Kebudayaan | E24: Baik | F24: 1500000 | G24: Suzuki Bravo | H24: 1993 | I24: BH 7948 AZ | J24: MHDA100VxDS274243 | K24: A100.ID.161699
A25: 3 | B25: Sepeda Motor | D25: Dinas Pendidikan dan Kebudayaan | E25: Baik | F25: 1500000 | G25: Suzuki A100 | H25: 1994 | I25: BH 8001 AZ | J25: MHDA100VxPJ274210 | K25: A100.ID.161665
A26: 4 | B26: Sepeda Motor | D26: Dinas Pendidikan dan Kebudayaan | E26: Baik | F26: 1500000 | G26: Suzuki Bravo | H26: 1994 | I26: BH 8054 AZ | J26: MHDRC100PPJ.112304 | K26: E104.ID335552
A27: 5 | B27: Sepeda Motor | D27: Dinas Pendidikan dan Kebudayaan | E27: Baik | F27: 1500000 | G27: Suzuki A100 | H27: 1994 | I27: BH 7945 AZ | J27: MHDA100VxPJ274302 | K27: A100.ID.161750
A28: 6 | B28: Sepeda Motor | D28: Dinas Pendidikan dan Kebudayaan | E28: Baik | F28: 1500000 | G28: Suzuki Bravo | H28: 1995 | I28: BH 7947 AZ | J28: MHDA100VxB | K28: A100.10161.728
A29: 7 | B29: Sepeda Motor | D29: Dinas Pendidikan dan Kebudayaan | E29: Baik | F29: 1500000 | G29: Suzuki Bravo | H29: 1995 | I29: BH 8030 AZ | J29: MHJA100VPJ274325 | K29: A100.70161.156
A30: 8 | B30: Sepeda Motor | D30: Dinas Pendidikan dan Kebudayaan | E30: Baik | F30: 2000000 | G30: Suzuki A100 | H30: 1996 | I30: BH 5386 AZ | J30: MHDA1006x0635720 | K30: A10016215411
A31: 9 | B31: Sepeda Motor | D31: Dinas Pendidikan dan Kebudayaan | E31: Baik | F31: 2000000 | G31: Suzuki Bravo | H31: 1997 | I31: BH 8034 AZ
A32: 10 | B32: Sepeda Motor | D32: Dinas Pendidikan dan Kebudayaan | E32: Baik | F32: 2000000 | G32: Suzuki A100 | H32: 1997 | I32: BH 5383 AZ | J32: MHDA100VxVJ.338704 | K32: A100.ID.215446
A33: 11 | B33: Sepeda Motor | D33: Dinas Pendidikan dan Kebudayaan | E33: Baik | F33: 2000000 | G33: Suzuki A100 | H33: 1997 | I33: BH 8031 HZ | J33: MHDA100VxPJ
A34: 12 | B34: Sepeda Motor | D34: Dinas Pendidikan dan Kebudayaan | E34: Baik | F34: 2000000 | G34: Suzuki Bravo | H34: 1997 | I34: BH 9545 HZ | J34: MHDRC.100 PVJ/329385 | K34: E.104-10-551398
A35: 13 | B35: Sepeda Motor | D35: Dinas Pendidikan dan Kebudayaan | E35: Baik | F35: 2000000 | G35: Suzuki Bravo | H35: 1997 | I35: BH 8124 AZ | J35: MHDA100.VxVY538527 | K35: A100.ID.215235
A36: 14 | B36: Sepeda Motor | C36: Ada | D36: Dinas Pendidikan dan Kebudayaan | E36: Rusak Berat | F36: 8000000 | G36: Honda Win | H36: 2005 | I36: BH 5315 GZ | J36: MH1HABD155K119070 | K36: HABDE-1118239 | L36: D-5514963 | N36: Gudang
A37: 15 | B37: Sepeda Motor | C37: Ada | D37: Dinas Pendidikan dan Kebudayaan | E37: Rusak Berat | F37: 8000000 | G37: Honda Win | H37: 2005 | I37: BH 5318 GZ | J37: MH1HABD165K118400 | K37: HABDE-1118272 | L37: D-5514956 | N37: Gudang
A38: 16 | B38: Sepeda Motor | C38: Ada | D38: Dinas Pendidikan dan Kebudayaan | E38: Rusak Berat | F38: 8000000 | G38: Honda Win | H38: 2005 | I38: BH 5317 GZ | J38: MH1HABD165K119269 | K38: HABDE-1118838 | L38: D-5514955 | N38: Gudang
A39: 17 | B39: Sepeda Motor | C39: Ada | D39: Dinas Pendidikan dan Kebudayaan | E39: Rusak Berat | F39: 8000000 | G39: Honda Win | H39: 2005 | I39: BH 5316 GZ | J39: MH1HABD175K119152 | K39: HABDE-1118647 | L39: D-5514964 | N39: Gudang
A40: 18 | B40: Sepeda Motor | C40: Ada | D40: Dinas Pendidikan dan Kebudayaan | E40: Rusak Berat | F40: 9550000 | G40: Honda Supra Fit | H40: 2007 | I40: BH 5586 GZ | J40: MH1HB32127K316352 | K40: HB32E-1313071 | L40: E-7787714 | N40: Gudang
A41: 19 | B41: Sepeda Motor | C41: Ada | D41: Dinas Pendidikan dan Kebudayaan | E41: Rusak Berat | F41: 9550000 | G41: Honda Supra Fit | H41: 2007 | I41: BH 5587 GZ | J41: MH1HB32147K316448 | K41: HB32E-1313078 | L41: E-7787704 | N41: Gudang
A42: 20 | B42: Sepeda Motor | C42: Ada | D42: Dinas Pendidikan dan Kebudayaan | E42: Rusak Berat | F42: 9550000 | G42: Honda Supra Fit | H42: 2007 | I42: BH 5622 GZ | J42: MH1HB32187K303136 | K42: HB32E-1295669 | L42: E-7787678 | N42: Gudang
A43: 21 | B43: Sepeda Motor | C43: Ada | D43: Dinas Pendidikan dan Kebudayaan | E43: Rusak Berat | F43: 9550000 | G43: Honda Supra Fit | H43: 2007 | I43: BH 5592 GZ | J43: MH1HB32157K300243 | K43: HB32E-1278496 | L43: E-7787668 | N43: Gudang
...

Sheet 02. Dinas Kesehatan
A2: KARTU INVENTARIS BARANG ( KIB )
A3: B. PERALATAN MESIN ( KENDARAAN RODA 4 ( EMPAT ) DAN 2 ( DUA )
A6: PEMERINTAH PROVINSI | C6: : JAMBI
A7: KABUPATEN / KOTA | C7: : MUARO JAMBI
A8: UNIT ORGANISASI | C8: : DINAS KESEHATAN
A9: no | B9: spesifikasi | C9: spesifikasi_lainnya | D9: Merk | E9: unit_kerja | F9: kondisi | G9: harga | H9: rehab | I9: merk | J9: type | K9: bahan | L9: tahun | M9: satuan | N9: jumlah | O9: umur_ekonomis | P9: no_sertifikat | Q9: no_polisi | R9: no_rangka | S9: no mesin | T9: no bpkb | U9: tgl_ada | V9: keterangan | W9: pengguna
A10: 1 | B10: Micro Bus ( Penumpang 15 S/D 29 Orang ) | C10: Micro Bus | E10: Dinas Kesehatan | F10: Baik | G10: 268400000 | H10: 0 | I10: Besi+ Baja | L10: 2009 | M10: Unit | N10: 1 | O10: 7 | Q10: BH 7502 G EX BH 422 GZ EX BH 604 GZ | R10: MHCNK55EY9J026342 | S10: M026342 | T10: F-8676057 | U10: ada | V10: RSUD Sungai Gelam
A11: 2 | B11: Mini Bus ( Penumpang 14 Orang Kebawah ) | C11: Minibus | E11: Dinas Kesehatan | F11: Baik | G11: 110000000 | H11: 0 | I11: Besi + Baja | L11: 2002 | M11: Unit | N11: 1 | O11: 7 | Q11: BH 1264 G EX BH 332 GZ | R11: MHF11KF7020035692 | S11: 7K-0479015 | T11: C-1667739 | U11: ada | V11: Dinas Kesehatan (RUSAK BERAT)
A12: 3 | B12: Mini Bus ( Penumpang 14 Orang Kebawah ) | C12: Minibus | E12: Dinas Kesehatan | F12: Baik | G12: 132000000 | H12: 0 | I12: Besi + Baja | L12: 2004 | M12: Unit | N12: 1 | O12: 7 | Q12: BH 1266 G EX BH 1042 GZ | R12: MHFXW426442009300 | S12: 1TR-6019734 | T12: D-3117754 | U12: ada | V12: Dinas Kesehatan
A13: 4 | B13: Mini Bus ( Penumpang 14 Orang Kebawah ) | C13: Minibus | E13: Dinas Kesehatan | F13: Baik | G13: 65000000 | H13: 0 | I13: Besi + Baja | L13: 2005 | M13: Unit | N13: 1 | O13: 7 | Q13: BH 1050 GZ | R13: MHYGDN41V535J-133989 | S13: G1SAID-134473 | T13: D-7511940 | U13: ada | V13: AHMAD RIPIN | W13: di Rumah R. Fauzi Rasor
A14: 5 | B14: Mini Bus ( Penumpang 14 Orang Kebawah ) | C14: Minibus | E14: Dinas Kesehatan | F14: Baik | G14: 102000000 | H14: 0 | I14: Besi + Baja | L14: 2005 | M14: Unit | N14: 1 | O14: 7 | Q14: BH 1075 GZ | R14: MHYESL 4153J-539080 | S14: GISA-IA-539080 | T14: C-5101477 | U14: ada | V14: BPKB ADA, Perubahan Nopol dari BH 53 GZ, 34 GZ jadi BH 1075 GZ (RUSAK BERAT)
A15: 6 | B15: Mini Bus ( Penumpang 14 Orang Kebawah ) | C15: Minivan | E15: Dinas Kesehatan | F15: Baik | G15: 129900000 | H15: 0 | I15: Besi + Baja | L15: 2007 | M15: Unit | N15: 1 | O15: 7 | Q15: BH 1180 G EX BH 40 GZ | R15: MJJFC522KOO2743 | S15: TB002727 | T15: F-0923441
A16: 7 | B16: Mini Bus ( Penumpang 14 Orang Kebawah ) | C16: Minibus | E16: Dinas Kesehatan | F16: Baik | G16: 175000000 | H16: 0 | I16: Besi + Baja | L16: 2007 | M16: Unit | N16: 1 | O16: 7 | Q16: BH 1057 GZ | R16: MHCTBR54FGK250098 | S16: E280098 | T16: E-1991172 | U16: ada | V16: Dinas Kesehatan (RUSAK BERAT)
A17: 8 | B17: Mini Bus ( Penumpang 14 Orang Kebawah ) | C17: Minibus | E17: Dinas Kesehatan | F17: Baik | G17: 199550000 | H17: 0 | I17: Besi + Baja | L17: 2010 | M17: Unit | N17: 1 | O17: 7 | Q17: BH 1330 G EX BH 410 GZ EX BH 1123 GZ | R17: MHFE2CJ2JAK016743 | S17: DBU4353 | T17: H-O 4610849 | U17: ada | V17: Reclass Dari set Lain RB
A18: 9 | B18: Mini Bus ( Penumpang 14 Orang Kebawah ) | C18: Minibus | E18: Dinas Kesehatan | F18: Baik | G18: 141000000 | H18: 0 | I18: Besi + Baja | J18: Ertiga | L18: 2012 | M18: Unit | N18: 1 | O18: 7 | Q18: BH 1346 G EX BH 1147 GZ | R18: MHYKZE81SCJ-105638 | S18: K14BT-1006068 | T18: I-11593447 | V18: RSUD AHMAD RIPIN | W18: Dr. Spesialis
A19: 10 | B19: Mini Bus ( Penumpang 14 Orang Kebawah ) | C19: Minibus | E19: Dinas Kesehatan | F19: Baik | G19: 188200000 | H19: 0 | I19: Besi+ Baja | L19: 2012 | M19: Unit | N19: 1 | O19: 7 | Q19: BH 1347 G EX BH 1167 G EX BH 1175 GZ EX BH 42 GZ | R19: MHFE2CJ2JCK031971 | S19: DDB3016 | T19: J-04079880 | U19: ada | V19: SEI.GELAM
A20: 11 | B20: Mini Bus ( Penumpang 14 Orang Kebawah ) | C20: Minibus | E20: Dinas Kesehatan | F20: Baik | G20: 141000000 | H20: 0 | I20: Besi + Baja | J20: Ertiga | L20: 2012 | M20: Unit | N20: 1 | O20: 7 | Q20: BH 1148 GZ | R20: MHYKZE81SCJ-104022 | S20: K14BT- 1004235 | T20: I-11593448 | V20: RSUD AHMAD RIPIN | W20: Dr. Spesialis
A21: 12 | B21: Mini Bus ( Penumpang 14 Orang Kebawah ) | C21: Minibus | E21: Dinas Kesehatan | F21: Baik | G21: 169800000 | H21: 0 | I21: Besi + Baja | L21: 2013 | M21: Unit | N21: 1 | O21: 7 | Q21: BH 1262 G EX BH 1192 GZ | R21: MHYKZE8 1SDJ 100555 | S21: K14BT - 1035142 | T21: K-03088177 | V21: RSUD AHMAD RIPIN
A22: 13 | B22: Mini Bus ( Penumpang 14 Orang Kebawah ) | C22: Minibus | E22: Dinas Kesehatan | F22: Baik | G22: 169800000 | H22: 0 | I22: Besi + Baja | L22: 2013 | M22: Unit | N22: 1 | O22: 7 | Q22: BH 1261 G EX BH 1191 GZ | R22: MHYKZE81SDJ - 100351 | S22: K14BT - 1035148 | T22: K-03088176 | V22: RSUD AHMAD RIPIN
A23: 14 | B23: Mini Bus ( Penumpang 14 Orang Kebawah ) | C23: Minibus | E23: Dinas Kesehatan | F23: Baik | G23: 186050000 | H23: 0 | I23: Besi + Baja | L23: 2013 | M23: Unit | N23: 1 | O23: 7 | Q23: BH 1201 G EX BH 41 GZ | R23: MHFE2CJ2JDKO35877 | S23: DD14702 | T23: K-02786816 | U23: ada | V23: Reclass Dari set Lain RB
A24: 15 | B24: Mini Bus ( Penumpang 14 Orang Kebawah ) | C24: Minibus | E24: Dinas Kesehatan | F24: Baik | G24: 195000000 | H24: 0 | I24: Besi + Baja | L24: 2014 | M24: Unit | N24: 1 | O24: 7 | Q24: BH 1235 G EX BH 1205GZ | R24: MHYLZG81SDJ201233 | S24: K14BT1078081 | T24: K-06090825 | U24: ada
A25: 16 | B25: Mini Bus ( Penumpang 14 Orang Kebawah ) | C25: Mobil Roda 4 | E25: Dinas Kesehatan | F25: Baik | G25: 217800000 | H25: 0 | L25: 2017 | M25: Unit | N25: 1 | O25: 7 | Q25: BH 1007 G | R25: MHKM5EB4JHK006700 | S25: 1NRF265264 | T25: L-10936795 | U25: ada | V25: RSU Sungai Bahar
A26: 17 | B26: Mini Bus ( Penumpang 14 Orang Kebawah ) | C26: Kendaraan roda empat | E26: Dinas Kesehatan | F26: Baik | G26: 256700000 | H26: 0 | I26: Besi | L26: 2019 | M26: Unit | N26: 1 | O26: 7 | Q26: BH 1046 G | T26: 0 | V26: Direktur RSU Sungai Bahar
A27: 18 | B27: Mini Bus ( Penumpang 14 Orang Kebawah ) | C27: Kendaraan Roda Empat | E27: Dinas Kesehatan | F27: Baik | G27: 162000000 | H27: 0 | I27: Besi + Baja | L27: 2020 | M27: Unit | N27: 1 | O27: 7 | Q27: BH 1301 G | R27: MHKV3BA6JLK013755 | S27: K3MH69502 | T27: P-06450335 | U27: ada
A28: 19 | B28: Mini Bus ( Penumpang 14 Orang Kebawah ) | C28: Kendaraan Roda Empat | E28: Dinas Kesehatan | F28: Baik | G28: 413000000 | H28: 0 | I28: Besi + Baja | L28: 2020 | M28: Unit | N28: 1 | O28: 7 | Q28: BH 1088 G | R28: MHFAW8EM4L0214883 | S28: 1TR-A729433 | T28: 0 | V28: KEPALA DINAS
A29: 20 | B29: Mini Bus ( Penumpang 14 Orang Kebawah ) | C29: Kendaraan Roda Empat | E29: Dinas Kesehatan | F29: Baik | G29: 347000000 | H29: 0 | I29: Besi + Baja | L29: 2020 | M29: Unit | N29: 1 | O29: 7 | Q29: BH 1087 G | R29: MHFJB8EM2L1066920 | S29: 2GD-C677880 | T29: 0 | W29: Mutasi ke DPRD
A30: 21 | B30: Mobil Donor Darah | C30: Hiace M/T | E30: Dinas Kesehatan | F30: Baik | G30: 1100000000 | H30: 0 | J30: Hiace | L30: 2024 | M30: Unit | N30: 1 | O30: 7 | Q30: BH 9038 G | R30: JTFST22P6R0046765 | S30: 1KD-B190110 | T30: U-02080764 | U30: ada | V30: RSUD AHMAD RIPIN | W30: RSUD AHMAD RIPIN/ UPD Darah
A31: 22 | B31: Mini Bus ( Penumpang 14 Orang ke Bawah ) | C31: Toyota Avanza 1.3 E. M/T / Ambulance | E31: Dinas Kesehatan | F31: Baik | G31: 349800000 | H31: 0 | I31: Toyota | K31: Besi | L31: 2025 | M31: Unit | N31: 1 | O31: 7 | Q31: BH 9047 G | R31: MHKAA1BY9S1005467 | S31: 1NRG309655 | T31: 0 | V31: Dinkes AMBULAN TEMPINO | W31: Dinkes
A32: 23 | B32: Mini Bus ( Penumpang 14 Orang ke Bawah ) | C32: Toyota Avanza 1.3 E. M/T / Ambulance | E32: Dinas Kesehatan | F32: Baik | G32: 349800000 | H32: 0 | I32: Toyota | K32: Besi | L32: 2025 | M32: Unit | N32: 1 | O32: 7 | Q32: BH 9045 G | R32: MHKAA1BY1S1005480 | T32: 0 | V32: Dinkes JMBI KECIL | W32: Dinkes
A33: 24 | B33: Mini Bus ( Penumpang 14 Orang ke Bawah ) | C33: Toyota Avanza 1.3 E. M/T / Ambulance | E33: Dinas Kesehatan | F33: Baik | G33: 349800000 | H33: 0 | I33: Toyota | K33: Besi | L33: 2025 | M33: Unit | N33: 1 | O33: 7 | Q33: BH 9046 G | R33: MHKAA1BY1S1005530 | T33: 0 | V33: Pkm. Muaro Kumpeh | W33: Ambulance rawat inap
A34: 25 | B34: Mini Bus ( Penumpang 14 Orang ke Bawah ) | C34: Toyota Innova 2.4 G. M/T / Ambulance | E34: Dinas Kesehatan | F34: Baik | G34: 649800000 | H34: 0 | I34: Toyota | J34: Kijang Inova 2.4 G /MT | K34: Besi | L34: 2025 | M34: Unit | N34: 1 | O34: 7 | Q34: BH 9048 G | R34: MHFIB8EM551175340 | S34: 2GD5873243 | T34: AA00086546 | V34: Pkm. Tanjung | W34: Pkm. Tanjung
A35: 26 | B35: Pick Up | C35: Mobil Box | E35: Dinas Kesehatan | F35: Baik | G35: 209802160 | H35: 0 | I35: Besi | L35: 2016 | M35: Unit | N35: 1 | O35: 7 | Q35: BH 9361 GZ | R35: MHCTBR54FGK175469 | S35: E175469 | T35: L-08629036 | U35: ada | V35: Instalasi Farmasi
A36: 27 | B36: Mobil Ambulance | C36: Ambulance | E36: Dinas Kesehatan | F36: Baik | G36: 54817000 | H36: 0 | I36: Besi | L36: 1992 | M36: Unit | N36: 1 | O36: 7 | Q36: BH 9016 BZ | R36: KF50-091389 | S36: 5K-9053199 | T36: 9190860 | U36: ada | V36: Raden Mustofa (SUDAH LELANG)
A37: 28 | B37: Mobil Ambulance | C37: Pusling | E37: Dinas Kesehatan | F37: Baik | G37: 116750000 | H37: 0 | I37: Besi + Baja | L37: 2003 | M37: Unit | N37: 1 | O37: 7 | Q37: BH 2012 GZ | R37: MHF11KF8030080842 | S37: 7K-0606988 | T37: C-5973506 | U37: ada | V37: Pkm. Tan Tan (SUDAH LELANG)
A38: 29 | B38: Mobil Ambulance | C38: Pusling | D38: Toyota Kijang | E38: Dinas Kesehatan | F38: RB | G38: 116000000 | H38: 0 | I38: Besi + Baja | L38: 2003 | M38: Unit | N38: 1 | O38: 7 | Q38: BH 1089 GZ | R38: MHFIIKF8030080842 | S38: 7K-0606988 | T38: 0 | V38: Pkm. Tempino | W38: Usulkan Lelang 2026
A39: 30 | B39: Mobil Ambulance | C39: Ambulance | D39: Toyota KIjang L200 | E39: Dinas Kesehatan | F39: Baik | G39: 175000000 | H39: 0 | I39: Besi + Baja | L39: 2004 | M39: Unit | N39: 1 | O39: 7 | Q39: BH 9315 GZ | R39: MMBCNK5704F000614 | S39: 4M40ZA0702 | T39: D-3116629 | U39: ada | V39: Pkm Sungai Bahar VII
A40: 31 | B40: Mobil Ambulance | C40: Pusling | E40: Dinas Kesehatan | F40: Baik | G40: 80000000 | H40: 0 | I40: Besi + Baja | L40: 2004 | M40: Unit | N40: 1 | O40: 7 | Q40: BH 9311 GZ | R40: MHML300DB3RZ32380 | S40: 4D56-390012 | T40: C-7206020 | V40: RS A RIPIN
A41: 32 | B41: Mobil Ambulance | C41: Ambulance | E41: Dinas Kesehatan | F41: Baik | G41: 59000000 | H41: 0 | I41: Besi + Baja | L41: 2006 | M41: Unit | N41: 1 | O41: 7 | Q41: BH 9317 GZ | R41: MHKSPRRHE6K003366 | S41: 9298255 | T41: D-9865431 | U41: ada | V41: Dinas Kesehatan
A42: 33 | B42: Mobil Ambulance | C42: Pusling | E42: Dinas Kesehatan | F42: Baik | G42: 153150000 | H42: 0 | I42: Besi + Baja | L42: 2007 | M42: Unit | N42: 1 | O42: 7 | Q42: BH 8140 G EX BH 9018 GZ | R42: MROAW12G870005042 | S42: 1TR6404434 | T42: F-2415815 | U42: ada | V42: Gudang Farmasi
A43: 34 | B43: Mobil Ambulance | C43: Perbaikan Kendaraan Roda 4 ( Pusling ) | E43: Dinas Kesehatan | F43: Baik | G43: 59705000 | H43: 0 | L43: 2007 | M43: Unit | N43: 1 | O43: 7 | T43: 0
...

Sheet 03. DPUPR
A2: KARTU INVENTARIS BARANG ( KIB )
A3: B. PERALATAN MESIN ( KENDARAAN RODA 4 ( EMPAT ) DAN 2 ( DUA )
A6: PEMERINTAH PROVINSI | C6: : JAMBI
A7: KABUPATEN / KOTA | C7: : MUARO JAMBI
A8: UNIT ORGANISASI | C8: : DINAS PEKERJAAN UMUM DAN PENATAAN RUANG
A9: no | B9: spesifikasi | C9: spesifikasi_lainnya | D9: unit_kerja | E9: kondisi | F9: harga | G9: merk | H9: tahun | I9: KEBERADAAN SAAT PEMERIKSAAN | J9: no_polisi | K9: no_rangka | L9: no_mesin | M9: no_bpkb | N9: Pengguna
B10: KENDARAAN DINAS BERMOTOR PERORANGAN | F10: 1813250000
A11: 1 | B11: Multi Purpose Vehicle (MPV) | C11: Kijang Standar | D11: Dinas Pekerjaan Umum dan Penataan Ruang | E11: RB | F11: 85000000 | G11: Toyota | H11: 2000 | J11: BH 1277 G | K11: MHF11KF70Y0031224 | L11: 7K-0372156 | M11: B-0009508 | N11: Rusak Berat (Usulan Lelang)
A12: 2 | B12: Multi Purpose Vehicle (MPV) | C12: Innova Luxury V | D12: Dinas Pekerjaan Umum dan Penataan Ruang | E12: Baik | F12: 265500000 | G12: Toyota | H12: 2012 | J12: BH 1135 G EXS BH 27 GZ | K12: MHFXW43G8C4070098 | L12: ITR 7379385 | M12: J-01541391 | N12: Kepala Dinas
A13: 3 | B13: Multi Purpose Vehicle (MPV) | C13: Rush Type S | D13: Dinas Pekerjaan Umum dan Penataan Ruang | E13: Baik | F13: 194600000 | G13: Toyota | H13: 2013 | J13: BH 1170 G | K13: MHFE2CJ3JDK062840 | L13: DDK6793 | M13: K-00104004 | N13: Sekretaris Dinas
A14: 4 | B14: Multi Purpose Vehicle (MPV) | C14: Rush Type S | D14: Dinas Pekerjaan Umum dan Penataan Ruang | E14: Baik | F14: 194600000 | G14: Toyota | H14: 2013 | I14: Ada | J14: BH 1171 G EXS BH 272 GZ | K14: MHFE2CJ3JDK062733 | L14: DDK5526 | M14: K-00104005 | N14: Kepala Bidang Jasa Konstruksi
A15: 5 | B15: Multi Purpose Vehicle (MPV) | C15: Rush TRD | D15: Dinas Pekerjaan Umum dan Penataan Ruang | E15: Baik | F15: 217850000 | G15: Toyota | H15: 2013 | J15: BH 1196 G EXS BH 275 GZ | K15: MHFE2CJ3JDK072742 | L15: DDY6661 | M15: K-03202460 | N15: Kepala Bidang Pengairan
A16: 6 | B16: Multi Purpose Vehicle (MPV) | C16: Rush TRD | D16: Dinas Pekerjaan Umum dan Penataan Ruang | E16: Baik | F16: 217850000 | G16: Toyota | H16: 2013 | J16: BH 1203 G | K16: MHFE2CJ3JDK072195 | L16: DDY0728 | M16: K-03202459 | N16: Kepala Bidang Bina Marga
A17: 7 | B17: Multi Purpose Vehicle (MPV) | C17: Rush TRD | D17: Dinas Pekerjaan Umum dan Penataan Ruang | E17: Baik | F17: 217850000 | G17: Toyota | H17: 2013 | J17: BH 1202 G EXS BH 273 GZ | K17: MHFE2CJ3JDK073634 | L17: DDZ5807 | M17: K-03202458 | N17: Kepala Bidang Cipta Karya dan Penataan Ruang
A18: 8 | B18: Sport Utility Vehicle (SUV) | C18: Pajero Sport GLX 4x4 MT | D18: Dinas Pekerjaan Umum dan Penataan Ruang | E18: Baik | F18: 420000000 | G18: Mitsubishi | H18: 2014 | J18: BH 1237 G | K18: MMBGNKH40ED019576 | L18: 4D56UCFB5407 | M18: K-06092841 | N18: Kepala Dinas
B19: KENDARAAN BERMOTOR ANGKUTAN BARANG | F19: 4212616400
A20: 1 | B20: Truck + Attachment | C20: Dyna 130 PS HT High Gear PS | D20: Dinas Pekerjaan Umum dan Penataan Ruang | E20: Baik | F20: 300000000 | G20: Toyota | H20: 2012 | J20: BH 8152 G | K20: MHFC1JU43C5064582 | L20: W04DT-RJ66224 | M20: J-04375795 | N20: Kepala UPTD
A21: 2 | B21: Pick Up | C21: Panter Pick Up Turbo | D21: Dinas Pekerjaan Umum dan Penataan Ruang | E21: RB | F21: 21875000 | G21: Isuzu | H21: 2014 | J21: BH 8126 G EXS BH 9356 GZ | K21: MHCTBR54FEK169811 | L21: E169811 | M21: K-06099461 | N21: Rusak Berat (Usulan Lelang)
A22: 3 | B22: Truck + Attachment | C22: Colt Diesel FE 74 HDV | D22: Dinas Pekerjaan Umum dan Penataan Ruang | E22: Baik | F22: 294482400 | G22: Mitsubushi | H22: 2014 | J22: BH 8125 GZ | K22: MHMFE74P5EK129587 | L22: 4D34T-K69879 | M22: K-06098627 | N22: Kepala UPTD
A23: 4 | B23: Truck + Attachment | C23: 136 HDX DUMP TRUK DROP SIDE 4,5 M3 | D23: Dinas Pekerjaan Umum dan Penataan Ruang | E23: Baik | F23: 583448000 | G23: Hino | H23: 2025 | J23: BH 8042 G | K23: MJECCB2FXS5028545 | L23: N04CWYJ38981 | M23: W-07720296
A24: 5 | B24: Truck + Attachment | C24: 136 HDX DUMP TRUK DROP SIDE 4,5 M3 | D24: Dinas Pekerjaan Umum dan Penataan Ruang | E24: Baik | F24: 583448000 | G24: Hino | H24: 2025 | J24: BH 8043 G | K24: MJECCB2F6S5028591 | L24: N04CWYJ39022 | M24: W-07720297
A25: 6 | B25: Truck + Attachment | C25: 136 HDX DUMP TRUK DROP SIDE 4,5 M3 | D25: Dinas Pekerjaan Umum dan Penataan Ruang | E25: Baik | F25: 583448000 | G25: Hino | H25: 2025 | J25: BH 8044 G | K25: MJECCB2F1S5028529 | L25: N04CWYJ38975 | M25: W-07720298
A26: 7 | B26: Truck + Attachment | C26: 136 HDX DUMP TRUK DROP SIDE 4,5 M3 | D26: Dinas Pekerjaan Umum dan Penataan Ruang | E26: Baik | F26: 583448000 | G26: Hino | H26: 2025 | J26: BH 8046 G | K26: MJECCB2F8S5028558 | L26: N04CWYJ39003 | M26: W-07720300
A27: 8 | B27: Truck + Attachment | C27: 136 HDX DUMP TRUK DROP SIDE 4,5 M3 | D27: Dinas Pekerjaan Umum dan Penataan Ruang | E27: Baik | F27: 583448000 | G27: Hino | H27: 2025 | J27: BH 8047 G | K27: MJECCB2F6S5028557 | L27: N04CWYJ39004 | M27: W-07720301
A28: 9 | B28: Truck + Attachment | C28: 136 HDL Truk Pengangkut Alat Berat (Winch 10 T) | D28: Dinas Pekerjaan Umum dan Penataan Ruang | E28: Baik | F28: 679019000 | G28: Hino | H28: 2025 | J28: BH 8045 G | K28: MJEECB2F1S5006670 | L28: N0CWYJ39666 | M28: W-07720299
B29: KENDARAAN BERMOTOR BERODA DUA | F29: 969639500
A30: 1 | B30: Sepeda Motor | C30: Win Type M.CB | D30: Dinas Pekerjaan Umum dan Penataan Ruang | E30: RB | F30: 5000000 | G30: Honda | H30: 2000 | J30: BH 5029 GZ | K30: MHIHABA101K056894 | L30: HABAE-1056832 | M30: B-0620750 | N30: Rusak Berat (Usulan Lelang)
A31: 2 | B31: Sepeda Motor | C31: Supra | D31: Dinas Pekerjaan Umum dan Penataan Ruang | E31: RB | F31: 6000000 | G31: Honda | H31: 2001 | J31: BH 5055 GZ | K31: MH1KEV381K132676 | L31: KEV3E-1132846 | N31: Operasional Bidang Sekretariat
A32: 3 | B32: Sepeda Motor | C32: GL MAX | D32: Dinas Pekerjaan Umum dan Penataan Ruang | E32: RB | F32: 8000000 | G32: Honda | H32: 2004 | J32: BH 5274 GZ | K32: MH1UABE144K070682 | L32: UABEE-1070472 | M32: D-0410433 | N32: Rusak Berat (Usulan Lelang)
A33: 4 | B33: Sepeda Motor | C33: GL MAX | D33: Dinas Pekerjaan Umum dan Penataan Ruang | E33: RB | F33: 8000000 | G33: Honda | H33: 2004 | J33: BH 5272 GZ | K33: MH1UABE114K070350 | L33: UABEE-1070435 | M33: D-0410431 | N33: Satrio Aji Prasojo, ST
A34: 5 | B34: Sepeda Motor | C34: GL MAX | D34: Dinas Pekerjaan Umum dan Penataan Ruang | E34: RB | F34: 8000000 | G34: Honda | H34: 2004 | J34: BH 2489 G | K34: MH1UABR144K069502 | L34: UABEE-1068830 | N34: Ahmad Sodiqin, S.Kom (Bid. BM)
A35: 6 | B35: Sepeda Motor | C35: Supra Fit | D35: Dinas Pekerjaan Umum dan Penataan Ruang | E35: RB | F35: 7000000 | G35: Honda | H35: 2004 | J35: BH 5275 GZ | K35: MH1HB21164K265722 | L35: HB21E-1265560 | M35: D-1606007 | N35: Rahma Mastofani, SE
A36: 7 | B36: Sepeda Motor | C36: Mega Pro Type GL 160 D | D36: Dinas Pekerjaan Umum dan Penataan Ruang | E36: Baik | F36: 17755000 | G36: Honda | H36: 2009 | J36: BH 5852 GZ | K36: MH1KCIII59K235583 | L36: KC11E1237519 | M36: G-0276778 | N36: Ricky Eka Putra, SE (Bid. Pengairan)
A37: 8 | B37: Sepeda Motor | C37: Mega Pro | D37: Dinas Pekerjaan Umum dan Penataan Ruang | E37: Baik | F37: 17755000 | G37: Honda | H37: 2009 | I37: Ada | J37: BH 2654 G (EX BH 5850 GZ) | K37: MH1KC11129K235668 | L37: KC11E1237612
A38: 9 | B38: Sepeda Motor | C38: Mega Pro GL 160 D | D38: Dinas Pekerjaan Umum dan Penataan Ruang | E38: Baik | F38: 17755000 | G38: Honda | H38: 2009 | I38: Ada | J38: BH 2410 G | K38: MH1KC111X9K235661 | L38: KC11E1237648 | M38: G-0276779 | N38: Abdul Rasyid, ST
A39: 10 | B39: Sepeda Motor | C39: Mega Pro | D39: Dinas Pekerjaan Umum dan Penataan Ruang | E39: Baik | F39: 17755000 | G39: Honda | H39: 2009 | I39: Ada | J39: BH 2428 G | K39: MH1KCIII49K235669 | L39: KC11E1237630 | M39: G-0276722 | N39: Amri (Bid. Pengairan)
A40: 11 | B40: Sepeda Motor | C40: Mega Pro | D40: Dinas Pekerjaan Umum dan Penataan Ruang | E40: RB | F40: 17755000 | G40: Honda | H40: 2009 | J40: BH 2409 G | K40: MH1KC11109K235667 | L40: KC11E1237614 | M40: G-0276777
A41: 12 | B41: Sepeda Motor | C41: New Mega Pro CW | D41: Dinas Pekerjaan Umum dan Penataan Ruang | E41: Baik | F41: 18075000 | G41: Honda | H41: 2011 | I41: ADA | J41: BH 2537 G | K41: MH1KC311XBK153317 | L41: KC31E-1153057 | M41: I-05804043 | N41: M. Hairul Roji, ST (Pengawas)
A42: 13 | B42: Sepeda Motor | C42: New Mega Pro CW | D42: Dinas Pekerjaan Umum dan Penataan Ruang | E42: Baik | F42: 18075000 | G42: Honda | H42: 2011 | I42: ADA | J42: BH 2566 G | K42: MH1KC3111BK159491 | L42: KC31E-1160130 | N42: Sumartono, S.Sos (Fungsional Tehnik Jalan dan Jembatan)
A43: 14 | B43: Sepeda Motor | C43: New Mega Pro CW | D43: Dinas Pekerjaan Umum dan Penataan Ruang | E43: Baik | F43: 18075000 | G43: Honda | H43: 2011 | I43: ADA | J43: BH 2623 G | K43: MH1KC3112BK159466 | L43: KC31E 1159955 | M43: I-05804045 | N43: Ferdi Fadlan Hamdani, ST, MT (Fungsional Tehnik Jalan dan Jembatan)
...

Sheet 04. Perkim
A2: KARTU INVENTARIS BARANG ( KIB )
A3: B. PERALATAN MESIN ( KENDARAAN RODA 4 ( EMPAT ) DAN 2 ( DUA )
A6: PEMERINTAH PROVINSI | C6: : JAMBI
A7: KABUPATEN / KOTA | C7: : MUARO JAMBI
A8: UNIT ORGANISASI | C8: : DINAS PERUMAHAN DAN KAWASAN PERMUKIMAN
A9: no | B9: spesifikasi | C9: spesifikasi_lainnya | D9: unit_kerja | E9: kondisi | F9: harga | G9: merk | H9: tahun | I9: no_polisi | J9: no_rangka | K9: no_mesin | L9: no_bpkb | M9: Keterangan | N9: Pengguna | O9: UPDATE
B10: KENDARAAN DINAS BERMOTOR PERORANGAN | F10: =SUM(F11:F15) -> 1306100000
A11: 1 | B11: Multi Purpose Vehicle (MPV) | C11: Minibus | D11: Perkim | E11: Baik | F11: 225000000 | G11: Isuzu Phanter Adventure | H11: 2012 | I11: BH 1156 G | J11: MHCTBR54FCK315810 | K11: E315810 | L11: M-11771787 | N11: Baik (Baru Diperbaiki) | O11: Sekdis/ baik
A12: 2 | B12: Multi Purpose Vehicle (MPV) | C12: Multi Purpose Vehicle (MPV) | D12: Perkim | E12: Baik | F12: 373600000 | G12: Toyota-Kijang Inova | H12: 2017 | I12: BH 1004 G | J12: MHFAW8EM3H0205115 | K12: ITR-A247234 | L12: L-10935830 | N12: Kepala Dinas | O12: kadis / baik
A13: 3 | B13: Multi Purpose Vehicle (MPV) | C13: Kendaraan Roda 4 | D13: Perkim | E13: Baik | F13: 205500000 | H13: 2019 | N13: Sudah dimutasi ke DLH
A14: 4 | B14: Sport Utility Vehicle (SUV) | C14: Sport Utility Vehicle (SUV) | D14: Perkim | E14: Baik | F14: 251000000 | G14: TOYOTA RUSH -1.5 G M/T ALL NEW | H14: 2019 | I14: BH 1051 G | J14: MHKE8FA2JKJ000259 | K14: 2NRF903179 | L14: P-06385530 | M14: Reklas dari Kendaraan Bermotor Khusus | N14: Kepala Bidang Permukiman | O14: kabid/ RR
A15: 5 | B15: Sport Utility Vehicle (SUV) | C15: Sport Utility Vehicle (SUV) | D15: Perkim | E15: Baik | F15: 251000000 | G15: TOYOTA RUSH -1.5 G M/T ALL NEW | H15: 2019 | I15: BH 1052 G | J15: MHKE8FA2JKK008126 | K15: 2NRF909639 | L15: P-06385531 | M15: Reklas dari Kendaraan Bermotor Khusus | N15: Kepala Bidang PSU | O15: kabid PSU/baik
B16: KENDARAAN BERMOTOR BERODA DUA | F16: =SUM(F17:F34) -> 380114100
A17: 1 | B17: Sepeda Motor | C17: Sepeda Motor | D17: Perkim | E17: Baik | F17: 16905000 | G17: Honda Mega Pro CW 160 DB | H17: 2009 | I17: BH 2406 G exs BH 5840 GZ | J17: MH1KC11179K211222 | K17: KC11E-1213402 | L17: F-8688107 | M17: BH 5840 GZ/BH 2406 G | N17: Armen Sutera (Bendahara Pengeluaran) | O17: Bend. Pengeluaran/RR
A18: 2 | B18: Sepeda Motor | C18: Sepeda Motor | D18: Perkim | E18: Baik | F18: 16905000 | G18: Honda Mega Pro CW 160 DB | H18: 2009 | I18: BH 2407 G exs BH 5841 GZ | J18: MH1KC11189K211102 | K18: KC11E-1213316 | L18: F-8688108 | M18: BH 5841 GZ/BH 2407 G | N18: Adam Malik (Fungsional umum) | O18: Fungsional Umum/ baik
A19: 3 | B19: Sepeda Motor | C19: Sepeda Motor Roda 2 | D19: Perkim | E19: Baik | F19: 15455700 | G19: Honda Verza 150 CW | H19: 2013 | I19: BH 2202 G/ EX BH 6225 GZ | J19: MHIKC5215DK023801 | K19: KC52E1024057 | L19: K-01753071 | M19: EX BH 6225 GZ | N19: Operasional Bidang Sekretariat | O19: Plt. kasubag keuangan/baik
A20: 4 | B20: Sepeda Motor | C20: Sepeda Motor Roda 2 | D20: Perkim | E20: Baik | F20: 15455700 | G20: Honda Verza 150 CW | H20: 2013 | I20: BH 2212 G/ EX BH 6224 GZ | J20: MHIKC5218DK024571 | K20: KC52E1024675 | L20: K-01753056 | M20: EX BH 6224 GZ | N20: Sarizal Efendi (Pembantu PPK SKPD) | O20: Pemb. PPPK SKPD/baik
A21: 5 | B21: Sepeda Motor | C21: Sepeda Motor Roda 2 | D21: Perkim | E21: Baik | F21: 22555000 | G21: Yamaha New Aerox 155 VVA (standar Version) | H21: 2018 | I21: BH 2048 G | J21: MH3SG4610HJ079912 | K21: G3J1E-0118500 | L21: M-11807738 | N21: Meti Erinawati, S.HI (Fungsional Tehnik Penyehatan Lingkungan) | O21: Fungsional Teknis/ baik
A22: 6 | B22: Sepeda Motor | C22: Sepeda Motor Roda 2 | D22: Perkim | E22: Baik | F22: 22555000 | G22: Yamaha New Aerox 155 VVA (standar Version) | H22: 2018 | I22: BH 2049 G | J22: MH3SG4610HJ060844 | K22: G3J1E- 0087931 | L22: M-11807739 | N22: Rahmat Supriadi (Fungsional Tehnik Tata Bangunan dan Perumahan) | O22: Fungsional Teknis/ baik
A23: 7 | B23: Sepeda Motor | C23: Sepeda Motor Roda 2 | D23: Perkim | E23: Baik | F23: 22555000 | G23: Yamaha New Aerox 155 VVA (standar Version) | H23: 2018 | I23: BH 2050 G | J23: MH3SG4610HJ080499 | K23: G3J1E-0118977 | L23: M-11807740 | N23: Nyimas Yabin, SE (Fungsional Tehnik Tata Bangunan dan Perumahan) | O23: Fungsional Teknis/ baik
A24: 8 | B24: Sepeda Motor | C24: Sepeda Motor Roda 2 | D24: Perkim | E24: Baik | F24: 22555000 | G24: Yamaha New Aerox 155 VVA (standar Version) | H24: 2018 | I24: BH 2051 G | J24: MH3SG4610HJ080493 | K24: G3J1E-0119081 | L24: M-11807741 | N24: Ade Rahmat Kurniawan (PPK SKPD) | O24: Kasubag Perencanaan/baik
A25: 9 | B25: Sepeda Motor | C25: Sepeda Motor Roda 2 | D25: Perkim | E25: Baik | F25: 22555000 | G25: Yamaha New Aerox 155 VVA (standar Version) | H25: 2018 | I25: BH 2052 G | J25: MH3SG4610HJ079917 | K25: G3J1E-0118504 | L25: M-11807742 | N25: Dewi Utami (Pembantu PPK SKPD) | O25: Fungsional Umum/ baik
A26: 10 | B26: Sepeda Motor | C26: Sepeda Motor Roda 2 | D26: Perkim | E26: Baik | F26: 22555000 | G26: Yamaha New Aerox 155 VVA (standar Version) | H26: 2018 | I26: BH 2053 G | J26: MH3SG4610HJ069680 | K26: G3J1E-0099157 | L26: M-11807743 | N26: Maradhona Habibie, ST (Fungsional Tehnik Penyehatan Lingkungan) | O26: Fungsional Teknis/ baik
A27: 11 | B27: Sepeda Motor | C27: Sepeda Motor Roda 2 | D27: Perkim | E27: Baik | F27: 22555000 | G27: Yamaha New Aerox 155 VVA (standar Version) | H27: 2018 | I27: BH 2054 G | J27: MH3SG4610HJ062553 | K27: G3J1E-0089919 | L27: M-11807744 | N27: Zulkifli, SH (Fungsional Tehnik Tata Bangunan dan Perumahan) | O27: Fungsional Teknis/ baik
A28: 12 | B28: Sepeda Motor | C28: Sepeda Motor Roda 2 | D28: Perkim | E28: Baik | F28: 22555000 | G28: Yamaha New Aerox 155 VVA (standar Version) | H28: 2018 | I28: BH 2055 G | J28: MH3SG4610HJ069371 | K28: G3J1E-0098830 | L28: M-11807745 | N28: Sri Anggraini, SH (Fungsional Tehnik Tata Bangunan dan Perumahan) | O28: Fungsional Teknis/ baik
A29: 13 | B29: Sepeda Motor | C29: Sepeda Motor Roda 2 | D29: Perkim | E29: Baik | F29: 22555000 | G29: Yamaha New Aerox 155 VVA (standar Version) | H29: 2018 | I29: BH 2056 G | J29: MH3SG4610HJ070445 | K29: G3J1E-0100551 | L29: M-11807746 | N29: Heriyanto (Fungsional Teknis) | O29: Fungsional Teknis/ baik
A30: 14 | B30: Sepeda Motor | C30: Sepeda Motor Roda 2 | D30: Perkim | E30: Baik | F30: 16811700 | G30: Honda Scoopy Vin 2018 | H30: 2018 | I30: BH 2101 G | J30: MH1JM312XJK191033 | K30: JM31E-2186114 | L30: O-00840721 | N30: Lita Agusta (Bendahara Pengeluaran Pembantu) | O30: Bend. Gajibaik
A31: 15 | B31: Kendaraan Roda Dua | C31: Yamaha Lexi 125 cc | D31: Perkim | E31: Baik | F31: 22216000 | G31: Yamaha Lexi | H31: 2023 | I31: BH 2386 G | J31: MH3SEF310PJ266533 | K31: E31VE-0338826 | L31: T-04344624 | M31: DISPERKIM | N31: Adha Riadi, A.Md (Bendahara Pengeluaran Pembantu) | O31: BPP/baik
A32: 16 | B32: Kendaraan Bermotor Beroda Dua | C32: YAMAHA AEROX 155 CC | D32: Perkim | E32: Baik | F32: 27235000 | G32: YAMAHA AEROX 155 CC | H32: 2024 | I32: BH 2863 G | J32: MH3SG6410PJ291434 | K32: G3P4E-0212119 | L32: U-02070890 | N32: Erik Ahmad, ST (Fungsional Tehnik Tata Bangunan dan Perumahan) | O32: Fungsional Teknis/ baik
A33: 17 | B33: Kendaraan Bermotor Beroda Dua | C33: Yamaha Aerox 155 CC | D33: Perkim | E33: Baik | F33: 27235000 | G33: YAMAHA AEROX 155 CC | H33: 2024 | I33: BH 2862 G | J33: MH3SG6410PJ297979 | K33: G3P2E-0324845 | L33: U-02070889 | N33: Muhammad Kurniawan, SH (Fungsional Tehnik Tata Bangunan dan Perumahan) | O33: Fungsional Teknis/ baik
A34: 18 | B34: Kendaraan Bermotor Beroda Dua | C34: Yamaha Jupiter Z CW FI | D34: Perkim | E34: Baik | F34: 18900000 | G34: YAMAHA JUPITER Z CW FI | H34: 2024 | I34: BH 2864 G | J34: MH3UE1120RJ402580 | K34: E3R5E-0415089 | L34: U-02070891 | N34: Dudi Ruhian (Pengurus Barang Pengguna) | O34: Bend. Barang/baik

Sheet 05. Satpol PP
A2: KARTU INVENTARIS BARANG ( KIB )
A3: B. PERALATAN MESIN ( KENDARAAN RODA 4 ( EMPAT ) DAN 2 ( DUA )
A6: PEMERINTAH PROVINSI | C6: : JAMBI
A7: KABUPATEN / KOTA | C7: : MUARO JAMBI
A8: UNIT ORGANISASI | C8: : SATUAN POLISI PAMONG PRAJA
A9: no | B9: spesifikasi | C9: spesifikasi_lainnya | D9: unit_kerja | E9: kondisi | F9: harga | G9: merk | H9: tahun | I9: no_polisi | J9: no_rangka | K9: no_mesin | L9: no_bpkb | M9: keterangan | N9: Pengguna | O9: Jabatan Pengguna | P9: Usulan Lelang 2026
B10: KENDARAAN DINAS BERMOTOR PERORANGAN | F10: 1179370000
A11: 1 | B11: Minibus | D11: Satpol PP | E11: RB | F11: 50000000 | G11: Suzuki ST 150 Futura | H11: 2003 | I11: BH 1076 GZ | J11: MHYESL4153J539035 | K11: G15A-IA-539035 | M11: Rusak Berat | P11: Usulan Lelang
A12: 2 | B12: Mobil Patroli | D12: Satpol PP | E12: Baik | F12: 348250000 | G12: Mitsubishi New strada Triton | H12: 2012 | I12: BH 8110 G/ EX BH 9343 GZ/ EX BH 50 GZ | J12: MMBJNKB40CD015286 | K12: 4D56UCDA5187 | L12: I-10037985 | M12: BH 50 GZ/BH 9343 GZ/BH 8110 G (Rusak Ringan)
A13: 3 | B13: Sport Utility Vehicle (SUV) | D13: Satpol PP | E13: Baik | F13: 201400000 | G13: Toyota Rush 1500 VVTI Manual | H13: 2013 | I13: BH 1220 G/ EX BH 50 GZ/ EX BH 1185 GZ | J13: MHFE2CJ3JDK064859 | K13: DDN0868 | L13: K-02786533 | M13: BH 1185 GZ/BH 50 GZ/BH 1220 G | N13: Arif Rahman Hakim, S.Ag, MH | O13: Sekretaris
A14: 4 | B14: Multi Purpose Vehicle (MPV) | D14: Satpol PP | E14: Baik | F14: 389720000 | G14: TOYOTA Innova Venture 2.0 M/T | H14: 2018 | I14: BH 1022 G | J14: MHFAW8EM3J0210336 | K14: 1TRA484592 | L14: M-11828166 | M14: Mutasi ke DPTH 2026 | N14: Indra, S.Sos
A15: 5 | B15: Multi Purpose Vehicle (MPV) | D15: Satpol PP | E15: Baik | F15: 190000000 | G15: TOYOTA AVANZA NEW 1.3 ESTD M/T | H15: 2020 | I15: BH 1095 G | J15: MHKM5EA2JLK079725 | K15: 1NRG096924 | L15: P-06421968 | M15: Kendaraan Dinas Operasional PPNS | N15: Evirawati, S.Sos | O15: Kepala Bidang Penegakan Perundang-Undangan Daerah
B16: KENDARAAN BERMOTOR ANGKUTAN BARANG | F16: 902500000
A17: 6 | B17: Pick Up | D17: Satpol PP | E17: Baik | F17: 135000000 | G17: Toyota KF60 | H17: 2004 | I17: BH 9312 GZ | J17: MHF31KF6040031559 | K17: 7K-0717070 | L17: D-0972420 | M17: Patroli | N17: Said Afnie, SE | O17: Kepala Sub Bagian Umum dan Keuangan
A18: 7 | B18: Mobil Dalmas | D18: Satpol PP | E18: Baik | F18: 354500000 | G18: Toyota Dyna/130 HT High Gear PS | H18: 2012 | I18: BH 8015 GZ | J18: MHFC1JU43C50604878 | K18: W04DTRI66545 | L18: J-04079882 | M18: Dalmas | N18: Iswandi Ali Basah,SH.,MH | O18: Kepala Sub Bagian Perencanaan dan Kepegawaian
A19: 8 | B19: Pick Up | D19: Satpol PP | E19: Baik | F19: 413000000 | G19: Toyota Hilux Double Cabin 2.4 E 4x4/T | H19: 2020 | I19: BH 8012 G | J19: MR0DB8CDXL0180926 | K19: 2GD-4815531 | L19: P-06451380 | M19: Patroli | N19: Moh. Haffis, SE | O19: Kepala Bidang Ketentraman dan Ketertiban Umum
A20: 9 | D20: Satpol PP | E20: Baik | G20: Toyota/Hilux 2.4V | H20: 2025 | I20: BH 8048 G | J20: MR0BB3CD2S5817352 | K20: 2GDD540718 | L20: W-0772339 | M20: Pengawalan Bupati | N20: Iskandar, S.Sos, MM | O20: Kepala Sub Bagian Perencanaa
B21: KENDARAAN BERMOTOR BERODA DUA | F21: 204000000
A22: 1 | B22: Sepeda Motor | D22: Satpol PP | E22: RB | F22: 9000000 | G22: Honda Supra X | H22: 2004 | I22: BH 5294 GZ | J22: MH1KEVA15YK786347 | K22: KEVAE-1785486 | L22: D-1608692 | M22: Rusak Berat | P22: Usulan Lelang
A23: 2 | B23: Sepeda Motor | D23: Satpol PP | E23: Baik | F23: 32500000 | G23: Honda CRF 150 LVIN | H23: 2019 | I23: BH 2169 G | J23: MH1KD1111KK090173 | K23: KD11E-1089473 | L23: P-06390277 | N23: Feri Irawan | O23: Fungsional/Pengelola Gaji
A24: 3 | B24: Sepeda Motor | D24: Satpol PP | E24: Baik | F24: 32500000 | G24: Honda CRF 150 LVIN | H24: 2019 | I24: BH 2170 G | J24: MH1KD1117KK091067 | K24: KD11E-1090368 | L24: P-06390278 | N24: Muhamad Syahril. SE | O24: Kepala Seksi Operasional dan Pengendalian
A25: 4 | B25: Sepeda Motor | D25: Satpol PP | E25: Baik | F25: 32500000 | G25: Honda CRF 150LVIN | H25: 2019 | I25: BH 2168 G | J25: MH1KD1112KK090182 | K25: KD11E-1089478 | L25: P-06390276 | N25: Adi Candra | O25: Bendahara Pengeluaran
A26: 5 | B26: Sepeda Motor | D26: Satpol PP | E26: Baik | F26: 32500000 | G26: Honda CRF 150 LVIN | H26: 2019 | I26: BH 2171 G | J26: MH1KD1111KK092375 | K26: KD11E-1091757 | L26: P-06390279 | N26: Andiansyah, S.Pdi | O26: Kepala Seksi Satuan Perlindungan Masyarakat
A27: 6 | B27: Sepeda Motor | D27: Satpol PP | E27: Baik | F27: 32500000 | G27: Honda CRF 150 LVIN | H27: 2019 | I27: BH 2166 G | J27: MH1KD1113KK092359 | K27: KD11E-1091741 | L27: P-06390274 | N27: Indra, S.Sos | O27: Plt. Kepala Seksi Pembinaan, Penyuluhan dan Pengawasan
A28: 7 | B28: Sepeda Motor | D28: Satpol PP | E28: Baik | F28: 32500000 | G28: Honda CRF 150 LVIN | H28: 2019 | I28: BH 2167 G | J28: MH1KD1114KK092371 | K28: KD11E-1091753 | L28: P-06390275 | N28: H.Harianto, SE | O28: Kepala Seksi Bina Potensi dan Kerjasama Masyarakat
A30: Mutasi dari Sekretariat Daerah (Kepala Satuan)
A31: 11 | B31: Jeep | C31: Mitsubishi Pajero Sport GLX | D31: SETDA | E31: Baik | F31: 510774000 | H31: 2017 | I31: BH 1008 G | J31: MMBGNKS30GH041595 | K31: Operasional Bagian Umum

Sheet 06. Damkar
A2: KARTU INVENTARIS BARANG ( KIB )
A3: B. PERALATAN MESIN ( KENDARAAN RODA 4 ( EMPAT ) DAN 2 ( DUA )
A6: PEMERINTAH PROVINSI | C6: : JAMBI
A7: KABUPATEN / KOTA | C7: : MUARO JAMBI
A8: UNIT ORGANISASI | C8: : PEMADAM KEBAKARAN DAN PENYELAMATAN
A9: no | B9: spesifikasi | C9: spesifikasi_lainnya | D9: unit_kerja | E9: kondisi | F9: harga | G9: merk | H9: tahun | I9: no_polisi | J9: no_rangka | K9: no_mesin | L9: no_bpkb | M9: keterangan | N9: Pengguna | O9: Update | P9: Kterangan
A10: 1 | B10: Minibus | D10: DAMKAR | E10: Baik | F10: 135000000 | G10: Toyota KF80 | H10: 2004 | I10: BH 340 GZ/ ex BH 26 GZ | J10: MHF11KF8040089127 | K10: 7K-0696096 | L10: D-0972414 | M10: BH 26 GZ/BH 340 GZ | N10: A. Marzuki, SE | O10: A. Marzuki, SE (Kabid Pemadaman dan penyelamatan) | P10: Hapus dari usulan lelang
A11: 2 | B11: Pick Up Single Cabin | D11: DAMKAR | E11: Baik | F11: 133000000 | G11: Toyota Hi Lux | H11: 2008 | I11: BH 8109 G/ ex BH 9328 GZ | J11: MR0AW12GX80014505 | K11: ITR-6661492 | L11: F-8679506 | M11: BH 9328 GZ/BH 8109 G | N11: M. Sugiarto, SH | O11: M. Sugiarto, SH (Kabid sarpras)
A12: 3 | B12: Damkar | D12: DAMKAR | E12: Baik | F12: 375000000 | G12: Mitsubishi FE349 | H12: 2004 | I12: BH 8008 GZ | J12: MHMFE349E4R059750 | K12: 4D34-419818 | L12: D-3117908 | M12: Mutasi dari Distakokeberta 3 Jan 2017 | N12: Herman Susilo, SE | O12: Fire Truck
A13: 4 | B13: Damkar | D13: DAMKAR | E13: Baik | F13: 846395000 | G13: Mitsubishi FE 74 | H13: 2007 | I13: BH 8014 GZ | J13: MHMFE74P47K000533 | K13: 4D34T-C21374 | L13: F-6038165 | M13: Mutasi dari Distakokeberta 3 Jan 2017 | N13: M. Sugiarto, SH | O13: Fire Truck
A14: 5 | B14: Damkar | D14: DAMKAR | E14: Baik | F14: 849500000 | G14: Mitsubih FE 74 125 PS | H14: 2008 | I14: BH 8012 GZ | J14: MHMFE74P48K013528 | K14: 4D34T-D37025 | L14: F-0929476 | M14: Mutasi dari Distakokeberta 3 Jan 2017 | N14: A. Marzuki, SE | O14: Fire Truck
A15: 6 | B15: Damkar | D15: DAMKAR | E15: Baik | F15: 849500000 | G15: Mitsubih FE 74 125 PS | H15: 2008 | I15: BH 8013 GZ | J15: MHMFE74P48K011951 | K15: 4D34T-D22515 | L15: F-0929477 | M15: Mutasi dari Distakokeberta 3 Jan 2017 | N15: Doni Suhedi, SE | O15: Fire Truck
A16: 7 | B16: Damkar | D16: DAMKAR | E16: Baik | F16: 1347500000 | G16: Toyota | H16: 2014 | I16: BH 8019 GZ | J16: MHFC1JU43E5118354 | K16: W04DT-RR16075 | L16: K-06101231 | M16: Mutasi dari Distakokeberta 3 Jan 2017 | N16: Herman Susilo, SE | O16: Fire Truck
A18: 1 | B18: Sepeda Motor | D18: DAMKAR | E18: Baik | F18: 7000000 | G18: Honda Supra Fit | H18: 2004 | I18: BH 5299 GZ | J18: MHIKEVA194K786383 | K18: KEVAE-1785344 | L18: D-1608697 | M18: Mutasi dari Setda Kendaraan Ex Dinas ESDM | N18: Reni Salfiyanti, SE | O18: Reni Salfiyanti, SE (Kasubbid Perencanaan)
A19: 2 | B19: Sepeda Motor | D19: DAMKAR | E19: Baik | F19: 9000000 | G19: Honda Supra Fit | H19: 2006 | I19: BH 5362 GZ | J19: MH1HB411125K156199 | K19: HB41E-1148444 | L19: D-7689692 | M19: Mutasi dari Distakokeberta 3 Jan 2017 | N19: Musohhiron, SH | O19: Irwanto, SE (Kabid Pencegahan)
A20: 3 | B20: Sepeda Motor | D20: DAMKAR | E20: Baik | F20: 17707200 | G20: Honda Mega Pro CW | H20: 2012 | I20: BH 6115 GZ | J20: MH1KC3114CK170762 | K20: KC31E-1170356 | L20: I-10608586 | M20: Mutasi dari Distakokeberta 3 Jan 2017 | N20: M. Hambali Hs, SE | O20: M. Hambali Hs, SE (Kasubbag umum dan kepegawaian)
A21: 4 | B21: Sepeda Motor | D21: DAMKAR | E21: Baik | F21: 17707200 | G21: Honda Mega Pro CW | H21: 2012 | I21: BH 6114 GZ | J21: MH1KC3117CK170982 | K21: KC31E-1170614 | L21: I-10608587 | M21: Mutasi dari Distakokeberta 3 Jan 2017 | N21: Musilimin | O21: Musilimin (Bendahara Pengeluaran)
A22: 5 | B22: Sepeda Motor | D22: DAMKAR | E22: Baik | F22: 34372000 | G22: Honda CRF 150 L | H22: 2025 | I22: BH 2946 G | J22: MH1KD1112SK641503 | K22: KD11E-1640695 | L22: W-01950781 | N22: Pitra Ramdhani | O22: Pitra Ramdhani (Koor pos Kumpeh Ulu)
A23: 6 | B23: Sepeda Motor | D23: DAMKAR | E23: Baik | F23: 34372000 | G23: Honda CRF 150 L/Merah | H23: 2025 | I23: BH 2947 G | J23: MH1KD1115SK641060 | K23: KD11E-1640237 | L23: W-01950782 | N23: Hendro | O23: Hendro (Pengurus Barang)
A24: 7 | B24: Sepeda Motor | D24: DAMKAR | E24: Baik | F24: 34372000 | G24: Honda CRF 150 L | H24: 2025 | I24: BH 2945 G | J24: MH1KD1113SK641557 | K24: KD11E-1640784 | L24: W-01950780 | N24: Heri Andriyadi | O24: Heri Andriyadi (Komandan Pos Sungai Bahar)
A25: 8 | B25: Sepeda Motor | D25: DAMKAR | E25: Baik | F25: 34372000 | G25: Honda CRF 150 L | H25: 2025 | I25: BH 2951 G | J25: MH1KD1111SK641539 | K25: KD11E-1640765 | L25: W-01950786 | N25: Hasbiallah | O25: Hasbiallah (Pengelola daftar gaji)

Sheet 07. Dinsos
A2: KARTU INVENTARIS BARANG ( KIB )
A3: B. PERALATAN MESIN ( KENDARAAN RODA 4 ( EMPAT ) DAN 2 ( DUA )
A6: PEMERINTAH PROVINSI | C6: : JAMBI
A7: KABUPATEN / KOTA | C7: : MUARO JAMBI
A8: UNIT ORGANISASI | C8: : DINAS SOSIAL, PP dan PA
A9: no | B9: spesifikasi | C9: spesifikasi_lainnya | D9: unit_kerja | E9: kondisi | F9: harga | G9: merk | H9: tahun | I9: no_polisi | J9: no_rangka | K9: no mesin | L9: no_bpkb | M9: keterangan | N9: Pengguna | O9: Jabatan Pengguna | P9: Usulan Lelang
B10: KENDARAAN BERMOTOR PENUMPANG | F10: =SUM(F11:F17) -> 2067915000
A11: 1 | B11: Mini Bus ( Penumpang 14 Orang Kebawah ) | D11: Dinas Sosial, PP dan PA | E11: Baik | F11: 232947000 | G11: Kijang Inova G | H11: 2010 | I11: BH 1103 G (EX BH 1115 G) | J11: MHFXW42GOA2160940 | K11: 1TR-6924969 | L11: H-01976588 | M11: Mutasi ke Damkar
A12: 2 | B12: Mini Bus ( Penumpang 14 Orang Kebawah ) | D12: Dinas Sosial, PP dan PA | E12: Baik | F12: 199815000 | G12: Isuzu Phanter Smash Tubo LM | H12: 2010 | I12: BH 1139 G | J12: MHCTBR54FAK303645 | K12: E303645 | L12: H-0 3141103 | M12: Mutasi ex Bahar Utara | N12: Azhari, S.Ag, M.Pdi | O12: Plt. Sekretaris
A13: 3 | B13: Mini Bus ( Penumpang 14 Orang Kebawah ) | D13: Dinas Sosial, PP dan PA | E13: Baik | F13: 267453000 | G13: KIA Sportege 2 M/T | H13: 2012 | I13: BH 44 GZ | J13: MJJSL5232CK000666 | K13: G4KDBS185892 | L13: I-10608291 | M13: Mutasi Aset Setda | N13: Ika Nurhayati,SE/Lelang | P13: Usulan Lelang 2026
A14: 4 | B14: Mini Bus ( Penumpang 14 Orang Kebawah ) | D14: Dinas Sosial, PP dan PA | E14: RR | F14: 233400000 | G14: Daihatsu LUXIO1,5X M/T | H14: 2017 | I14: BH 1002 G | J14: MHKW3CA3JGK016939 | K14: 3SZDGB0574 | L14: L-10935259 | M14: Mobil Perlindungan | N14: Yoppy Ariansyah, S.TP, MH | O14: Kepala Bidang Pemberdayaan Perempuan dan Perlindungan Anak
A15: 5 | B15: Mini Bus ( Penumpang 14 Orang Kebawah ) | D15: Dinas Sosial, PP dan PA | E15: Baik | F15: 347000000 | G15: All New Kijang Innova 2.4 GM/T | H15: 2020 | I15: BH 1310 G | J15: MHFJB8EM6L1074843 | K15: 2GD-C767118 | L15: P-07642253 | M15: Aset Dinas Sosial | N15: Drs. Rossa Candra Budy.,M.Pd | O15: Kepala Dinas
A16: 6 | B16: Mini Bus ( Penumpang 14 Orang Kebawah ) | D16: Dinas Sosial, PP dan PA | E16: Baik | F16: 332000000 | G16: Rush 1.5 S A/T GR Sport | H16: 2025 | I16: BH 1376 G | J16: MHKE8FB3JSKI08869 | K16: 2NR4E12847 | L16: AA00083074 | M16: Aset Dinas Sosial | N16: Sutinem, SP | O16: Kepala Bidang Rehabilitasi Sosial
A17: 7 | B17: Pick Up | D17: Dinas Sosial, PP dan PA | E17: Baik | F17: 455300000 | G17: Hilux Double Cabin 2.4 E (4X4) DSL M/T | H17: 2025 | I17: BH 8041G | J17: MR0DB8CD0S0134665 | K17: 2GDD498401 | L17: AA-00082977 | M17: Aset Dinas Sosial | N17: Rahmat Hidayat, S.Sos | O17: Kepala Bidang Perlindungan Jaminan Sosial dan Penanganan Fakir Miskin
B18: KENDARAAN BERMOTOR BERODA DUA | F18: =SUM(F19:F30) -> 217720000
A19: 1 | B19: Sepeda Motor | D19: Dinas Sosial, PP dan PA | E19: Baik | F19: 6000000 | G19: Honda WIN | H19: 2003 | I19: BH 5257 GZ | J19: MHIHABC133K016437 | K19: HABCE-1016393 | L19: C-4693222 | M19: Mutasi dari Setda | N19: Djunaidi Abu Padhil, S.Kom | O19: Jabatan Fungsional Perencanaan | P19: Usulan Lelang 2026
A20: 2 | B20: Sepeda Motor | D20: Dinas Sosial, PP dan PA | E20: Baik | F20: 8100000 | G20: Yamaha RX King | H20: 2004 | I20: BH 5276 GZ | J20: MH33KA0144K705086 | K20: 0047581F | M20: Mutasi dari Setda | N20: Ika Nurhayati,SE | O20: Pengelola Kesejahteraan Sosial/Pejabat Pengelola Barang SKPD
A21: 3 | B21: Sepeda Motor | D21: Dinas Sosial, PP dan PA | E21: Baik | F21: 12750000 | G21: Honda Supra X 125 TD | H21: 2008 | I21: BH 5795 GZ | J21: MHIJB811688K289890 | K21: JB81E-1286039 | L21: F-6858741 | M21: Mutasi dari BPPKB | N21: Rustiawati, S.Ag | O21: Jabatan Fungsional Penyuluh Sosial Ahli Muda
A22: 4 | B22: Sepeda Motor | D22: Dinas Sosial, PP dan PA | E22: Baik | F22: 15500000 | G22: Honda Supra X 125 | H22: 2011 | I22: BH 6048 GZ | J22: MHIJBF11XBK031556 | K22: JBF1E-1030719 | L22: I-05390862 | M22: Kendaraan Berada di DPPKB dan belum dimutasi
A23: 5 | B23: Sepeda Motor | D23: Dinas Sosial, PP dan PA | E23: Baik | F23: 16150000 | G23: Honda City Sport One | H23: 2011 | I23: BH 6023 GZ | J23: MHijba116bk130765 | K23: I02354451F | M23: Mutasi dari Setda | N23: Shanty, SE | O23: Analis Perencanaan Anggaran
A24: 6 | B24: Sepeda Motor | D24: Dinas Sosial, PP dan PA | E24: Baik | F24: 20525000 | G24: Yamaha Vixion | H24: 2012 | I24: BH 6107 GZ | J24: MH33C1005CK847583 | K24: 3CI-848318 | L24: I-10605018 | M24: Mutasi dari Setda | N24: Mira Marlina | O24: Jabatan Pengadministrasian Barang Milik Negara
A25: 7 | B25: Sepeda Motor | D25: Dinas Sosial, PP dan PA | E25: Baik | F25: 18921000 | G25: Honda New Vario 125 CBS ISS | H25: 2017 | I25: BH 2488 G | J25: MHIJFV112GK513198 | K25: JFV1E1520614 | L25: P-06416260 | M25: Mutasi dari Kemen | N25: Arif Rohman | O25: Pengadministrasian Perkantoran
A26: 8 | B26: Sepeda Motor | D26: Dinas Sosial, PP dan PA | E26: Baik | F26: 18921000 | G26: Honda New Vario 125 CBS ISS | H26: 2017 | I26: BH 2487 G | J26: MH1JFV116GK512930 | K26: JFV1E1520246 | L26: P-06416241 | M26: Mutasi dari Kemen | N26: Lindawati, S.Gz | O26: Jabatan Fungsional Analis Kebijakan Muda
A27: 9 | B27: Sepeda Motor | D27: Dinas Sosial, PP dan PA | E27: Baik | F27: 27100000 | G27: Yamaha N-Max 155 Non ABS | H27: 2020 | I27: BH 2298 G | J27: MH3SG3192LK014268 | K27: G3E4E-2069430 | L27: P-07662441 | M27: Aset Dinas Sosial | N27: Hairosani, S.IP | O27: Jabatan Fungsional Penyuluh Sosial Ahli Muda
A28: 10 | B28: Sepeda Motor | D28: Dinas Sosial, PP dan PA | E28: Baik | F28: 23500000 | G28: Yamaha Aerox 155 VVA | H28: 2020 | I28: BH 2293 G | J28: MH3SG4610LJ323012 | K28: G3JE-0529910 | L28: P-07661957 | M28: Aset Dinas Sosial | N28: Budiman, SE | O28: Bendahara Pengeluaran
A29: 11 | B29: Sepeda Motor | D29: Dinas Sosial, PP dan PA | E29: Baik | F29: 22500000 | G29: Honda Vario 150 Sporty | H29: 2021 | I29: BH 2328 G | J29: MH1KF4124MK435669 | K29: KF41E2439593 | L29: Q-09563794 | M29: Aset Dinas Sosial | N29: Pirdaus, SE | O29: Kepala Sub Bagian Umum dan Kepegawaian
A30: 12 | B30: Sepeda Motor | D30: Dinas Sosial, PP dan PA | E30: Baik | F30: 27753000 | G30: Honda VARIO 160 ABS MMC | H30: 2024 | I30: BH 2906 G | J30: MH1KFA112RK270055 | K30: KFA1E-1269750 | L30: V-01660434 | M30: Dinas Sosial, PP dan PA | N30: M. Joko Susanto | O30: Operator Data Penata Usaha Keuangan

Sheet 08. BPBD
A2: KARTU INVENTARIS BARANG ( KIB )
A3: B. PERALATAN DAN MESIN
A4: Periode Laporan 1900 - 2025
B8: PEMERINTAH PROPINSI | C8: : JAMBI
B9: KABUPATEN/KOTA | C9: : MUARO JAMBI
B10: URUSAN | C10: : URUSAN PILIHAN
B11: BIDANG | C11: : Ketentraman dan Ketertiban Umum Serta Perlindungan Masyarakat
B12: UNIT ORGANISASI | C12: : Badan Penanggulangan Bencana Daerah
A16: no | B16: spesifikasi | C16: spesifikasi lainnya | D16: unit kerja | E16: kondisi | F16: harga | G16: merk | H16: tahun | I16: no polisi | J16: no rangka | K16: no mesin | L16: no bpkb | M16: keterangan | N16: pengguna | O16: Update | P16: Keterangan
B17: PERALATAN DAN MESIN | F17: =F18 -> 1901820800
B18: ALAT ANGKUTAN DARAT BERMOTOR | F18: =F19 -> 1901820800
B19: ALAT ANGKUTAN DARAT BERMOTOR | F19: =F20+F22+F25+F35 -> 1901820800
B20: KENDARAAN DINAS BERMOTOR PERORANGAN | F20: =F21 -> 272000000
A21: 1 | B21: Sport Utility Vehicle (SUV) | D21: BPBD | E21: Baik | F21: 272000000 | G21: Toyota Rush 1,5 S A/T | H21: 2019 | I21: BH 1059 G | J21: MHKE8FB3JKJ001537 | K21: 2NRF902767 | L21: P-06385928 | N21: Sekretaris BPBD | O21: Sekretaris BPBD | P21: Baik
B22: KENDARAAN BERMOTOR ANGKUTAN BARANG | F22: =SUM(F23:F24) -> 615600000
A23: 1 | B23: Pick Up | D23: BPBD | E23: Baik | F23: 185000000 | G23: Mitsubishi L 300 | H23: 2018 | I23: B 9376 TTA | J23: MK2L0PU3377004969 | K23: 4D56C877712 | L23: O-00997551 | N23: Kabid KL | P23: Baik
A24: 2 | B24: Pick Up | D24: BPBD | E24: Baik | F24: 430600000 | G24: Mitsubishi Triton 2.4 LDC GLS (4x4) | H24: 2021 | I24: BH 8019 G | J24: MMBJJKL10MH040474 | K24: 4N15UHN7352 | L24: S-01518078 | N24: Kepala Badan | P24: Baik
B25: KENDARAAN BERMOTOR BERODA DUA | F25: =SUM(F26:F34) -> 232388200
A26: 1 | B26: Sepeda Motor | D26: BPBD | E26: Baik | F26: 17711100 | G26: Honda Mega Pro | H26: 2012 | I26: BH 6181 GZ | J26: MH1KC3117CK250282 | K26: KC31E-1250260 | L26: J-04077721 | N26: Kabid RR | O26: Operasional | P26: Baik
A27: 2 | B27: Sepeda Motor | D27: BPBD | E27: Baik | F27: 17711100 | G27: Honda Mega Pro | H27: 2012 | I27: BH 6180 GZ | J27: MH1KC3112CK247743 | K27: KC31E-1247439 | L27: J-04077722 | N27: Kasubbag TU | O27: Operasional | P27: Baik
A28: 3 | B28: Sepeda Motor | D28: BPBD | E28: Baik | F28: 33060000 | G28: Honda CRF 150L | H28: 2022 | I28: BH 2369 G | J28: MH1KDD111NK337955 | K28: KD11E-1337377 | L28: T-01477560 | N28: Darmulus | O28: Operasional | P28: Baik
A29: 4 | B29: Sepeda Motor | D29: BPBD | E29: Baik | F29: 33060000 | G29: Honda CRF 150L | H29: 2022 | I29: BH 2368 G | J29: MH1KD1111XNK340739 | K29: KD11E-1340023 | L29: T-01477559 | N29: Kabid KL | O29: Operasional | P29: Baik
A30: 5 | B30: Sepeda Motor Patroli | D30: BPBD | E30: Baik | F30: 26587000 | G30: Kawasaki LX 150 | H30: 2012 | I30: BH 2527 G | J30: MH4LX150CCKP53820 | K30: LX150CEP82912 | L30: P-07644772 | M30: Ex. B 6035 PTQ / NPH No. PRJ-32/BNPB/05/2016 | N30: Leni Fitriani | O30: Operasional | P30: Baik
A31: 6 | B31: Sepeda Motor Patroli | D31: BPBD | E31: Baik | F31: 26587000 | G31: Kawasaki LX 150 | H31: 2012 | I31: B 6034 PTQ | J31: MH4LX150CCKP53490 | K31: LX150CEP82893 | L31: J-01961235 | M31: NPH No. PRJ-32/BNPB/05/2016 | N31: Nasaruddin | O31: Operasional | P31: Di Gudang
A32: 7 | B32: Sepeda Motor Patroli | D32: BPBD | E32: Baik | F32: 21550000 | G32: Kawasaki KLX 150S | H32: 2013 | I32: BH 6228 GZ | J32: MH4LX150CDKP72632 | K32: LX150CEPB1912 | L32: K-01756469 | N32: Kabid PK | O32: Operasional | P32: Baik
A33: 8 | B33: Sepeda Motor Patroli | D33: BPBD | E33: Baik | F33: 28061000 | G33: Kawasaki KLX 150 S | H33: 2015 | I33: BH 2529 G | J33: MH4LX150CFJP28038 | K33: LX150CEPM5425 | L33: P-07644774 | M33: NPH No. PRJ-926/BNPB/09/2016 | N33: Sudarto, ST | O33: Operasional | P33: Baik
A34: 9 | B34: Sepeda Motor Patroli | D34: BPBD | E34: Baik | F34: 28061000 | G34: Kawasaki KLX 150 S | H34: 2015 | I34: BH 2528 G | J34: MH4LX150CFJP27995 | K34: LX150CEPM5187 | L34: P-07644773 | M34: NPH No. PRJ-926/BNPB/09/2016 (Ex B 6597 TQC) | N34: Hasan Basri | O34: Operasional | P34: Baik
B35: KENDARAAN BERMOTOR KHUSUS | F35: =SUM(F36:F37) -> 781832600
A36: 1 | B36: Mobil Tangki Air | D36: BPBD | E36: Baik | F36: 332420000 | G36: Isuzu NKR 71 HD | H36: 2014 | I36: B 9293 PMA | J36: MHCNKR71HEJ063054 | K36: B063054 | L36: L-08481401 | M36: NPH No. PRJ-350/BNPB/08/2016 | N36: Kabid KL | P36: Baik
A37: 2 | B37: Rescue Car | D37: BPBD | E37: Rusak Berat | F37: 449412600 | G37: Ford Ranger | H37: 2013 | I37: BH 8141 G | J37: MNBDMFF80CW150204 | K37: P4AT1058364 | L37: P-07742029 | M37: NPH No. PRJ-925/BNPB/09/2016 (Ex B 9015 PSD) | N37: Rusak Berat | P37: Di Bengkel
F38: =F17 -> 1901820800

Sheet 9. Nakertrans
A2: KARTU INVENTARIS BARANG ( KIB )
A3: B. PERALATAN MESIN ( KENDARAAN RODA 4 ( EMPAT ) DAN 2 ( DUA )
A6: PEMERINTAH PROVINSI | C6: : JAMBI
A7: KABUPATEN / KOTA | C7: : MUARO JAMBI
A8: UNIT ORGANISASI | C8: : DINAS TENAGA KERJA DAN TRANSMIGRASI
A9: no | B9: spesifikasi | C9: spesifikasi_lainnya | D9: unit_kerja | E9: kondisi | F9: harga | G9: merk | H9: tahun | I9: no_polisi | J9: no_rangka | K9: no_mesin | L9: no_bpkb | M9: pengguna
B10: KENDARAAN BERMOTOR PENUMPANG | F10: 583965000
A11: 1 | B11: Minibus | D11: Dinas Tenaga Kerja dan Transmigrasi | E11: Baik | F11: 110000000 | G11: Toyota KF80LX Standar | H11: 2004 | I11: BH 45 GZ | J11: MHF11KF8040091324 | K11: 7K-0719321 | L11: D-0972416F | M11: Ir. H. Muhammad Yamin | N11: Kadis Lamo/ Tarik
A12: 2 | B12: Minibus | D12: Dinas Tenaga Kerja dan Transmigrasi | E12: Baik | F12: 258965000 | G12: Toyota Rush | H12: 2016 | I12: BH 1297 G/ EX BH 1226 GZ | J12: MHFE2CJ3JGK111199 | K12: 3SZDFU8260 | L12: L-08617691F | M12: Wawan Suprianto.S.Sos,MH.
A13: 3 | B13: Minibus | D13: Dinas Tenaga Kerja dan Transmigrasi | E13: Baik | F13: 215000000 | G13: Toyota Avanza New Pelos | H13: 2018 | I13: BH 1024 G | J13: MHKM5EA4JJK025079 | K13: 1NRF391911 | L13: M-11829737F | M13: M. Amin. HS.SH.
B14: KENDARAAN BERMOTOR ANGKUTAN BARANG | F14: 318900000
A15: 4 | B15: Pick Up | D15: Dinas Tenaga Kerja dan Transmigrasi | E15: Baik | F15: 318900000 | G15: Mitsubishi Triton GLS 2,5 | H15: 2010 | I15: BH 8091 G/ EX BH 9331 G | J15: MMBJNKB40AD020811 | K15: 4D56UCBW4440 | L15: H-00769112F | M15: Operasional Kantor | N15: Kadis
B16: KENDARAAN BERMOTOR BERODA DUA | F16: 103705700
A17: 5 | B17: Sepeda Motor | D17: Dinas Tenaga Kerja dan Transmigrasi | E17: Baik | F17: 5500000 | G17: Honda Win | H17: 2003 | I17: BH 5255 GZ | J17: MHIHABC123K016493 | L17: C-4693220 | M17: Rusak Berat/digudang
A18: 6 | B18: Sepeda Motor | D18: Dinas Tenaga Kerja dan Transmigrasi | E18: Rusak Berat | F18: 10500000 | G18: Yamaha Vega R | H18: 2006 | I18: BH 5380 GZ | J18: MH33P90016K005396 | K18: 3P9-005360 | L18: D-8939620F | M18: Operasional Kantor
